Workbook

Sheet Algemene info
A2: Algemene informatie
A3: Voornaam
A4: Naam
A5: Geboortedatum
A6: Leeftijd | B6: =TRUNC(YEARFRAC(B5,TODAY())) -> 126

Sheet Intake vragen
A3: Klinische tekenen en symptomen | D3: Therapie
A4: Enuresis nocturna (bedplassen) | D4: Welke behandelingen al gevolgd?
A5: Aantal nachten per week? | D5: Sinds vorig consult
A6: Frequentie? (aantal keer per nacht) | D6: Dagkalender ingevuld?
A7: s nachts wakker worden om te plassen? | D7: Nachtkalender ingevuld?
A8: Tijdstip in de nacht? | D8: Drinkschema gevolgd?
A9: Draagt 's nachts een pamper? | D9: Superplassen uitgevoerd?
A10: Hoe groot is het urineverlies? | D10: Opvolging
A11: Incontinentie diurna | D11: Therapie op dit moment?
A12: Aantal dagen per week? | D12: Neemt medicatie?
A13: Frequentie? (aantal keer per dag
A14: Tijdstip ?
A15: Hoe groot is het urineverlies?
D17: Symptomen suggestief voor blaasdysfunctie
D18: Druppeltjes urineverlies in ondergoed
D19: • Voor mictie
D20: • Na mictie
D21: Grote hoeveelheid urineverlies ondergoed
D22: Aantal plasjes per dag
A23: subjectief gevoel van verbetering over verslechtering | D23: Intermittent verlies of continue lekkage
D24: Incontinentie diurna > 3,5 jaar oud
D25: Plots zeer dringend moeten plassen (urge)
D26: Ophoudmaneuvers
D27: Persmictie
D28: Frequent korte plasjes
D29: Onderbroken mictiestraal
D30: Urineweginfectie in voorgeschiedenis
D31: Ziekte en/of aangeboren afwijking aan nieren
D32: Ziekte en/of aangeboren afwijking aan urinewegen
D33: Ziekte en/of aangeboren afwijking aan ruggenmerg
G34: Toilethouding/hygiëne | J34: Mictie | M34: Situationeel
B35: samen in aanvink vak | G35: Gaat op school naar het toilet | J35: Plast in meerdere tijden | M35: Gigglingincontinentie
G36: Gaat zittend plassen | J36: Gaat zittend plassen | M36: Inspanningsgebonden last
G37: Neemt de tijd om te gaan plassen | J37: Neemt de tijd om te gaan plassen | M37: Urineverlies bij hoesten
G38: Blijft zitten tot volledig klaar | J38: Blijft zitten tot volledig klaar | M38: Koudegebonden last
G39: Plast over toiletbril (meisje) | J39: Plast over toiletbril? (meisje) | M39: Seizoensgebonden last
A41: Situationele last | B41: samen in aanvink vak
A42: Gigglingincontinentie?
A43: Inspanningsgebonden last?
A44: Urineverlies bij hoesten? | D44: Drankgewoontes
...

Sheet Dag 1
B1: Dag 1 op Kamp
B3: Ochtend | G3: Avond | L3: Uroflowmetrie en plasdagboek
B4: Plaswekker gebruikt | L4: Tot. VV (ml) | M4: =C22 -> 0
B5: Hoe vaak is plaswekker afgegaan | G5: Voldoende gedronken (> 1,5L) | J5: =IF(SUM(C30:V30)>1500,"Ja","Nee") -> Nee | L5: MVV (ml) | M5: =C20 -> 0
B6: Frequentie Urineverlies 's nachts | E6: 0 | G6: Natte broek gehad? | L6: GVV (ml) | M6: =C21 -> 0
B7: Natte luier? | G7: Frequentie urineverlies overdag
B8: Droog luiergewicht (g) | G8: Hoe vaak naar toilet geweest? | L8: Leeftijd | M8: ='Algemene info'!B6 -> 126
B9: Nat luiergewicht (g)
B10: Netto luiergewicht (g) | E10: =E9-E8 -> 0 | G10: EBCage (ml) | J10: =30+(M8*30) -> 3810
B11: Ochtendplas (ml) | E11: =SUMIF(C19:V19,"true",C16:V16) -> 0
B13: Waarden uit plasdagboek
C14: Plas 1 | D14: Plas 2 | E14: Plas 3 | F14: Plas 4 | G14: Plas 5 | H14: Plas 6 | I14: Plas 7 | J14: Plas 8 | K14: Plas 9 | L14: Plas 10 | M14: Plas 11 | N14: Plas 12 | O14: Plas 13 | P14: Plas 14 | Q14: Plas 15 | R14: Plas 16 | S14: Plas 17 | T14: Plas 18 | U14: Plas 19 | V14: Plas 20
B15: Tijdstip
B16: VV (ml)
B17: Faeces
B18: Toilet/urineverlies
B19: Nacht/Ochtend | C19: FALSE | D19: FALSE | E19: FALSE | F19: FALSE | G19: FALSE | H19: FALSE | I19: FALSE | J19: FALSE | K19: FALSE | L19: FALSE | M19: FALSE | N19: FALSE | O19: FALSE | P19: FALSE | Q19: FALSE | R19: FALSE | S19: FALSE | T19: FALSE | U19: FALSE | V19: FALSE
B20: MVV (ml) | C20: =MAX(C16:V16) -> 0
B21: GVV (ml) | C21: =IFERROR(AVERAGE(C16:V16),"0") -> 0
B22: Totale VV (ml) | C22: =SUM(C16:V16) -> 0
B24: Nachtelijke diurese = netto luiergewicht + ochtendplas (ml) | E24: =SUM(E10:E11) -> 0
B27: Waarden vochtinname
C28: Vochtinname 1 | D28: Vochtinname 2 | E28: Vochtinname 3 | F28: Vochtinname 4 | G28: Vochtinname 5 | H28: Vochtinname 6 | I28: Vochtinname 7 | J28: Vochtinname 8 | K28: Vochtinname 9 | L28: Vochtinname 10 | M28: Vochtinname 11 | N28: Vochtinname 12 | O28: Vochtinname 13 | P28: Vochtinname 14 | Q28: Vochtinname 15 | R28: Vochtinname 16 | S28: Vochtinname 17 | T28: Vochtinname 18 | U28: Vochtinname 19 | V28: Vochtinname 20
B29: Tijdstip
B30: Volume (ml)
B31: Type
B32: Totale vochtinname (ml) | C32: =SUM(C30:V30) -> 0
B34: Opmerkingen

Sheet Dag 2
B1: Dag 1 op Kamp
B3: Ochtend | G3: Avond | L3: Uroflowmetrie en plasdagboek
B4: Plaswekker gebruikt | L4: Tot. VV (ml) | M4: =C22 -> 0
B5: Hoe vaak is plaswekker afgegaan | G5: Voldoende gedronken (> 1,5L) | J5: =IF(SUM(C30:V30)>1500,"Ja","Nee") -> Nee | L5: MVV (ml) | M5: =C20 -> 0
B6: Frequentie Urineverlies 's nachts | E6: 0 | G6: Natte broek gehad? | L6: GVV (ml) | M6: =C21 -> 0
B7: Natte luier? | G7: Frequentie urineverlies overdag
B8: Droog luiergewicht (g) | G8: Hoe vaak naar toilet geweest? | L8: Leeftijd | M8: ='Algemene info'!B6 -> 126
B9: Nat luiergewicht (g)
B10: Netto luiergewicht (g) | E10: =E9-E8 -> 0 | G10: EBCage (ml) | J10: =30+(M8*30) -> 3810
B11: Ochtendplas (ml) | E11: =SUMIF(C19:V19,"true",C16:V16) -> 0
B13: Waarden uit plasdagboek
C14: Plas 1 | D14: Plas 2 | E14: Plas 3 | F14: Plas 4 | G14: Plas 5 | H14: Plas 6 | I14: Plas 7 | J14: Plas 8 | K14: Plas 9 | L14: Plas 10 | M14: Plas 11 | N14: Plas 12 | O14: Plas 13 | P14: Plas 14 | Q14: Plas 15 | R14: Plas 16 | S14: Plas 17 | T14: Plas 18 | U14: Plas 19 | V14: Plas 20
B15: Tijdstip
B16: VV (ml)
B17: Faeces
B18: Toilet/urineverlies
B19: Nacht/Ochtend | C19: FALSE | D19: FALSE | E19: FALSE | F19: FALSE | G19: FALSE | H19: FALSE | I19: FALSE | J19: FALSE | K19: FALSE | L19: FALSE | M19: FALSE | N19: FALSE | O19: FALSE | P19: FALSE | Q19: FALSE | R19: FALSE | S19: FALSE | T19: FALSE | U19: FALSE | V19: FALSE
B20: MVV (ml) | C20: =MAX(C16:V16) -> 0
B21: GVV (ml) | C21: =IFERROR(AVERAGE(C16:V16),"0") -> 0
B22: Totale VV (ml) | C22: =SUM(C16:V16) -> 0
B24: Nachtelijke diurese = netto luiergewicht + ochtendplas (ml) | E24: =SUM(E10:E11) -> 0
B27: Waarden vochtinname
C28: Vochtinname 1 | D28: Vochtinname 2 | E28: Vochtinname 3 | F28: Vochtinname 4 | G28: Vochtinname 5 | H28: Vochtinname 6 | I28: Vochtinname 7 | J28: Vochtinname 8 | K28: Vochtinname 9 | L28: Vochtinname 10 | M28: Vochtinname 11 | N28: Vochtinname 12 | O28: Vochtinname 13 | P28: Vochtinname 14 | Q28: Vochtinname 15 | R28: Vochtinname 16 | S28: Vochtinname 17 | T28: Vochtinname 18 | U28: Vochtinname 19 | V28: Vochtinname 20
B29: Tijdstip
B30: Volume (ml)
B31: Type
B32: Totale vochtinname (ml) | C32: =SUM(C30:V30) -> 0
B34: Opmerkingen

Sheet Dag 3
B1: Dag 1 op Kamp
B3: Ochtend | G3: Avond | L3: Uroflowmetrie en plasdagboek
B4: Plaswekker gebruikt | L4: Tot. VV (ml) | M4: =C22 -> 0
B5: Hoe vaak is plaswekker afgegaan | G5: Voldoende gedronken (> 1,5L) | J5: =IF(SUM(C30:V30)>1500,"Ja","Nee") -> Nee | L5: MVV (ml) | M5: =C20 -> 0
B6: Frequentie Urineverlies 's nachts | E6: 0 | G6: Natte broek gehad? | L6: GVV (ml) | M6: =C21 -> 0
B7: Natte luier? | G7: Frequentie urineverlies overdag
B8: Droog luiergewicht (g) | G8: Hoe vaak naar toilet geweest? | L8: Leeftijd | M8: ='Algemene info'!B6 -> 126
B9: Nat luiergewicht (g)
B10: Netto luiergewicht (g) | E10: =E9-E8 -> 0 | G10: EBCage (ml) | J10: =30+(M8*30) -> 3810
B11: Ochtendplas (ml) | E11: =SUMIF(C19:V19,"true",C16:V16) -> 0
B13: Waarden uit plasdagboek
C14: Plas 1 | D14: Plas 2 | E14: Plas 3 | F14: Plas 4 | G14: Plas 5 | H14: Plas 6 | I14: Plas 7 | J14: Plas 8 | K14: Plas 9 | L14: Plas 10 | M14: Plas 11 | N14: Plas 12 | O14: Plas 13 | P14: Plas 14 | Q14: Plas 15 | R14: Plas 16 | S14: Plas 17 | T14: Plas 18 | U14: Plas 19 | V14: Plas 20
B15: Tijdstip
B16: VV (ml)
B17: Faeces
B18: Toilet/urineverlies
B19: Nacht/Ochtend | C19: FALSE | D19: FALSE | E19: TRUE | F19: FALSE | G19: FALSE | H19: FALSE | I19: FALSE | J19: FALSE | K19: FALSE | L19: FALSE | M19: FALSE | N19: FALSE | O19: FALSE | P19: FALSE | Q19: FALSE | R19: FALSE | S19: FALSE | T19: FALSE | U19: FALSE | V19: FALSE
B20: MVV (ml) | C20: =MAX(C16:V16) -> 0
B21: GVV (ml) | C21: =IFERROR(AVERAGE(C16:V16),"0") -> 0
B22: Totale VV (ml) | C22: =SUM(C16:V16) -> 0
B24: Nachtelijke diurese = netto luiergewicht + ochtendplas (ml) | E24: =SUM(E10:E11) -> 0
B27: Waarden vochtinname
C28: Vochtinname 1 | D28: Vochtinname 2 | E28: Vochtinname 3 | F28: Vochtinname 4 | G28: Vochtinname 5 | H28: Vochtinname 6 | I28: Vochtinname 7 | J28: Vochtinname 8 | K28: Vochtinname 9 | L28: Vochtinname 10 | M28: Vochtinname 11 | N28: Vochtinname 12 | O28: Vochtinname 13 | P28: Vochtinname 14 | Q28: Vochtinname 15 | R28: Vochtinname 16 | S28: Vochtinname 17 | T28: Vochtinname 18 | U28: Vochtinname 19 | V28: Vochtinname 20
B29: Tijdstip
B30: Volume (ml)
B31: Type
B32: Totale vochtinname (ml) | C32: =SUM(C30:V30) -> 0
B34: Opmerkingen

Sheet Dag 4
B1: Dag 1 op Kamp
B3: Ochtend | G3: Avond | L3: Uroflowmetrie en plasdagboek
B4: Plaswekker gebruikt | L4: Tot. VV (ml) | M4: =C22 -> 0
B5: Hoe vaak is plaswekker afgegaan | G5: Voldoende gedronken (> 1,5L) | J5: =IF(SUM(C30:V30)>1500,"Ja","Nee") -> Nee | L5: MVV (ml) | M5: =C20 -> 0
B6: Frequentie Urineverlies 's nachts | E6: 0 | G6: Natte broek gehad? | L6: GVV (ml) | M6: =C21 -> 0
B7: Natte luier? | G7: Frequentie urineverlies overdag
B8: Droog luiergewicht (g) | G8: Hoe vaak naar toilet geweest? | L8: Leeftijd | M8: ='Algemene info'!B6 -> 126
B9: Nat luiergewicht (g)
B10: Netto luiergewicht (g) | E10: =E9-E8 -> 0 | G10: EBCage (ml) | J10: =30+(M8*30) -> 3810
B11: Ochtendplas (ml) | E11: =SUMIF(C19:V19,"true",C16:V16) -> 0
B13: Waarden uit plasdagboek
C14: Plas 1 | D14: Plas 2 | E14: Plas 3 | F14: Plas 4 | G14: Plas 5 | H14: Plas 6 | I14: Plas 7 | J14: Plas 8 | K14: Plas 9 | L14: Plas 10 | M14: Plas 11 | N14: Plas 12 | O14: Plas 13 | P14: Plas 14 | Q14: Plas 15 | R14: Plas 16 | S14: Plas 17 | T14: Plas 18 | U14: Plas 19 | V14: Plas 20
B15: Tijdstip
B16: VV (ml)
B17: Faeces
B18: Toilet/urineverlies
B19: Nacht/Ochtend | C19: FALSE | D19: FALSE | E19: FALSE | F19: FALSE | G19: FALSE | H19: FALSE | I19: FALSE | J19: FALSE | K19: FALSE | L19: FALSE | M19: FALSE | N19: FALSE | O19: FALSE | P19: FALSE | Q19: FALSE | R19: FALSE | S19: FALSE | T19: FALSE | U19: FALSE | V19: FALSE
B20: MVV (ml) | C20: =MAX(C16:V16) -> 0
B21: GVV (ml) | C21: =IFERROR(AVERAGE(C16:V16),"0") -> 0
B22: Totale VV (ml) | C22: =SUM(C16:V16) -> 0
B24: Nachtelijke diurese = netto luiergewicht + ochtendplas (ml) | E24: =SUM(E10:E11) -> 0
B27: Waarden vochtinname
C28: Vochtinname 1 | D28: Vochtinname 2 | E28: Vochtinname 3 | F28: Vochtinname 4 | G28: Vochtinname 5 | H28: Vochtinname 6 | I28: Vochtinname 7 | J28: Vochtinname 8 | K28: Vochtinname 9 | L28: Vochtinname 10 | M28: Vochtinname 11 | N28: Vochtinname 12 | O28: Vochtinname 13 | P28: Vochtinname 14 | Q28: Vochtinname 15 | R28: Vochtinname 16 | S28: Vochtinname 17 | T28: Vochtinname 18 | U28: Vochtinname 19 | V28: Vochtinname 20
B29: Tijdstip
B30: Volume (ml)
B31: Type
B32: Totale vochtinname (ml) | C32: =SUM(C30:V30) -> 0
B34: Opmerkingen

Sheet Dag 5
B1: Dag 1 op Kamp
B3: Ochtend | G3: Avond | L3: Uroflowmetrie en plasdagboek
B4: Plaswekker gebruikt | L4: Tot. VV (ml) | M4: =C22 -> 0
B5: Hoe vaak is plaswekker afgegaan | G5: Voldoende gedronken (> 1,5L) | J5: =IF(SUM(C30:V30)>1500,"Ja","Nee") -> Nee | L5: MVV (ml) | M5: =C20 -> 0
B6: Frequentie Urineverlies 's nachts | E6: 0 | G6: Natte broek gehad? | L6: GVV (ml) | M6: =C21 -> 0
B7: Natte luier? | G7: Frequentie urineverlies overdag
B8: Droog luiergewicht (g) | G8: Hoe vaak naar toilet geweest? | L8: Leeftijd | M8: ='Algemene info'!B6 -> 126
B9: Nat luiergewicht (g)
B10: Netto luiergewicht (g) | E10: =E9-E8 -> 0 | G10: EBCage (ml) | J10: =30+(M8*30) -> 3810
B11: Ochtendplas (ml) | E11: =SUMIF(C19:V19,"true",C16:V16) -> 0
B13: Waarden uit plasdagboek
C14: Plas 1 | D14: Plas 2 | E14: Plas 3 | F14: Plas 4 | G14: Plas 5 | H14: Plas 6 | I14: Plas 7 | J14: Plas 8 | K14: Plas 9 | L14: Plas 10 | M14: Plas 11 | N14: Plas 12 | O14: Plas 13 | P14: Plas 14 | Q14: Plas 15 | R14: Plas 16 | S14: Plas 17 | T14: Plas 18 | U14: Plas 19 | V14: Plas 20
B15: Tijdstip
B16: VV (ml)
B17: Faeces
B18: Toilet/urineverlies
B19: Nacht/Ochtend | C19: FALSE | D19: FALSE | E19: FALSE | F19: FALSE | G19: FALSE | H19: FALSE | I19: FALSE | J19: FALSE | K19: FALSE | L19: FALSE | M19: FALSE | N19: FALSE | O19: FALSE | P19: FALSE | Q19: FALSE | R19: FALSE | S19: FALSE | T19: FALSE | U19: FALSE | V19: FALSE
B20: MVV (ml) | C20: =MAX(C16:V16) -> 0
B21: GVV (ml) | C21: =IFERROR(AVERAGE(C16:V16),"0") -> 0
B22: Totale VV (ml) | C22: =SUM(C16:V16) -> 0
B24: Nachtelijke diurese = netto luiergewicht + ochtendplas (ml) | E24: =SUM(E10:E11) -> 0
B27: Waarden vochtinname
C28: Vochtinname 1 | D28: Vochtinname 2 | E28: Vochtinname 3 | F28: Vochtinname 4 | G28: Vochtinname 5 | H28: Vochtinname 6 | I28: Vochtinname 7 | J28: Vochtinname 8 | K28: Vochtinname 9 | L28: Vochtinname 10 | M28: Vochtinname 11 | N28: Vochtinname 12 | O28: Vochtinname 13 | P28: Vochtinname 14 | Q28: Vochtinname 15 | R28: Vochtinname 16 | S28: Vochtinname 17 | T28: Vochtinname 18 | U28: Vochtinname 19 | V28: Vochtinname 20
B29: Tijdstip
B30: Volume (ml)
B31: Type
B32: Totale vochtinname (ml) | C32: =SUM(C30:V30) -> 0
B34: Opmerkingen

Sheet Dag 6
B1: Dag 1 op Kamp
B3: Ochtend | G3: Avond | L3: Uroflowmetrie en plasdagboek
B4: Plaswekker gebruikt | L4: Tot. VV (ml) | M4: =C22 -> 0
B5: Hoe vaak is plaswekker afgegaan | G5: Voldoende gedronken (> 1,5L) | J5: =IF(SUM(C30:V30)>1500,"Ja","Nee") -> Nee | L5: MVV (ml) | M5: =C20 -> 0
B6: Frequentie Urineverlies 's nachts | E6: 0 | G6: Natte broek gehad? | L6: GVV (ml) | M6: =C21 -> 0
B7: Natte luier? | G7: Frequentie urineverlies overdag
B8: Droog luiergewicht (g) | G8: Hoe vaak naar toilet geweest? | L8: Leeftijd | M8: ='Algemene info'!B6 -> 126
B9: Nat luiergewicht (g)
B10: Netto luiergewicht (g) | E10: =E9-E8 -> 0 | G10: EBCage (ml) | J10: =30+(M8*30) -> 3810
B11: Ochtendplas (ml) | E11: =SUMIF(C19:V19,"true",C16:V16) -> 0
B13: Waarden uit plasdagboek
C14: Plas 1 | D14: Plas 2 | E14: Plas 3 | F14: Plas 4 | G14: Plas 5 | H14: Plas 6 | I14: Plas 7 | J14: Plas 8 | K14: Plas 9 | L14: Plas 10 | M14: Plas 11 | N14: Plas 12 | O14: Plas 13 | P14: Plas 14 | Q14: Plas 15 | R14: Plas 16 | S14: Plas 17 | T14: Plas 18 | U14: Plas 19 | V14: Plas 20
B15: Tijdstip
B16: VV (ml)
B17: Faeces
B18: Toilet/urineverlies
B19: Nacht/Ochtend | C19: FALSE | D19: FALSE | E19: FALSE | F19: FALSE | G19: FALSE | H19: FALSE | I19: FALSE | J19: FALSE | K19: FALSE | L19: FALSE | M19: FALSE | N19: FALSE | O19: FALSE | P19: FALSE | Q19: FALSE | R19: FALSE | S19: FALSE | T19: FALSE | U19: FALSE | V19: FALSE
B20: MVV (ml) | C20: =MAX(C16:V16) -> 0
B21: GVV (ml) | C21: =IFERROR(AVERAGE(C16:V16),"0") -> 0
B22: Totale VV (ml) | C22: =SUM(C16:V16) -> 0
B24: Nachtelijke diurese = netto luiergewicht + ochtendplas (ml) | E24: =SUM(E10:E11) -> 0
B27: Waarden vochtinname
C28: Vochtinname 1 | D28: Vochtinname 2 | E28: Vochtinname 3 | F28: Vochtinname 4 | G28: Vochtinname 5 | H28: Vochtinname 6 | I28: Vochtinname 7 | J28: Vochtinname 8 | K28: Vochtinname 9 | L28: Vochtinname 10 | M28: Vochtinname 11 | N28: Vochtinname 12 | O28: Vochtinname 13 | P28: Vochtinname 14 | Q28: Vochtinname 15 | R28: Vochtinname 16 | S28: Vochtinname 17 | T28: Vochtinname 18 | U28: Vochtinname 19 | V28: Vochtinname 20
B29: Tijdstip
B30: Volume (ml)
B31: Type
B32: Totale vochtinname (ml) | C32: =SUM(C30:V30) -> 0
B34: Opmerkingen

Sheet Dag 7
B1: Dag 1 op Kamp
B3: Ochtend | G3: Avond | L3: Uroflowmetrie en plasdagboek
B4: Plaswekker gebruikt | L4: Totaal VV (ml)
B5: Hoe vaak is plaswekker afgegaan | G5: Voldoende gedronken (> 1,5L) | J5: =IF(SUM(C30:V30)>1500,"Ja","Nee") -> Nee | L5: MVV (ml)
B6: Frequentie Urineverlies 's nachts | E6: 0 | G6: Natte broek gehad? | L6: GVV (ml)
B7: Natte luier? | G7: Frequentie urineverlies overdag
B8: Droog luiergewicht (g) | G8: Hoe vaak naar toilet geweest? | L8: Leeftijd | M8: ='Algemene info'!B6 -> 126
B9: Nat luiergewicht (g)
B10: Netto luiergewicht (g) | E10: =E9-E8 -> 0 | G10: EBCage (ml) | J10: =30+(M8*30) -> 3810
B11: Ochtendplas (ml) | E11: =SUMIF(C19:V19,"true",C16:V16) -> 0
B13: Waarden uit plasdagboek
C14: Plas 1 | D14: Plas 2 | E14: Plas 3 | F14: Plas 4 | G14: Plas 5 | H14: Plas 6 | I14: Plas 7 | J14: Plas 8 | K14: Plas 9 | L14: Plas 10 | M14: Plas 11 | N14: Plas 12 | O14: Plas 13 | P14: Plas 14 | Q14: Plas 15 | R14: Plas 16 | S14: Plas 17 | T14: Plas 18 | U14: Plas 19 | V14: Plas 20
B15: Tijdstip
B16: VV (ml)
B17: Faeces
B18: Toilet/urineverlies
B19: Nacht/Ochtend | C19: FALSE | D19: FALSE | E19: FALSE | F19: FALSE | G19: FALSE | H19: FALSE | I19: FALSE | J19: FALSE | K19: FALSE | L19: FALSE | M19: FALSE | N19: FALSE | O19: FALSE | P19: FALSE | Q19: FALSE | R19: FALSE | S19: FALSE | T19: FALSE | U19: FALSE | V19: FALSE
B20: MVV (ml) | C20: =MAX(C16:V16) -> 0
B21: GVV (ml) | C21: =IFERROR(AVERAGE(C16:V16),"0") -> 0
B22: Totale VV (ml) | C22: =SUM(C16:V16) -> 0
B24: Nachtelijke diurese = netto luiergewicht + ochtendplas (ml) | E24: =SUM(E10:E11) -> 0
B27: Waarden vochtinname
C28: Vochtinname 1 | D28: Vochtinname 2 | E28: Vochtinname 3 | F28: Vochtinname 4 | G28: Vochtinname 5 | H28: Vochtinname 6 | I28: Vochtinname 7 | J28: Vochtinname 8 | K28: Vochtinname 9 | L28: Vochtinname 10 | M28: Vochtinname 11 | N28: Vochtinname 12 | O28: Vochtinname 13 | P28: Vochtinname 14 | Q28: Vochtinname 15 | R28: Vochtinname 16 | S28: Vochtinname 17 | T28: Vochtinname 18 | U28: Vochtinname 19 | V28: Vochtinname 20
B29: Tijdstip
B30: Volume (ml)
B31: Type
B32: Totale vochtinname (ml) | C32: =SUM(C30:V30) -> 0
B34: Opmerkingen

Sheet Evolutie
B2: Waarde | D2: Dag 1 | E2: Dag 2 | F2: Dag 3 | G2: Dag 4 | H2: Dag 5 | I2: Dag 6 | J2: Dag 7
B3: Nachtelijke Diurese | D3: {=INDIRECT("'"&D2&"'!$C$23")} -> 0 | E3: {=INDIRECT("'"&E2&"'!$C$23")} -> 0 | F3: {=INDIRECT("'"&F2&"'!$C$23")} -> 0 | G3: {=INDIRECT("'"&G2&"'!$C$23")} -> 0 | H3: {=INDIRECT("'"&H2&"'!$C$23")} -> 0 | I3: {=INDIRECT("'"&I2&"'!$C$23")} -> 0 | J3: {=INDIRECT("'"&J2&"'!$C$23")} -> 0
B4: Voided volume PDB | C4: Max | D4: =INDIRECT("'"&D$2&"'!C20") -> 0 | E4: =INDIRECT("'"&E$2&"'!C20") -> 0 | F4: =INDIRECT("'"&F$2&"'!C20") -> 0 | G4: =INDIRECT("'"&G$2&"'!C20") -> 0 | H4: =INDIRECT("'"&H$2&"'!C20") -> 0 | I4: =INDIRECT("'"&I$2&"'!C20") -> 0 | J4: =INDIRECT("'"&J$2&"'!C20") -> 0
C5: Gemiddeld | D5: =INDIRECT("'"&D$2&"'!C21") -> 0 | E5: =INDIRECT("'"&E$2&"'!C21") -> 0 | F5: =INDIRECT("'"&F$2&"'!C21") -> 0 | G5: =INDIRECT("'"&G$2&"'!C21") -> 0 | H5: =INDIRECT("'"&H$2&"'!C21") -> 0 | I5: =INDIRECT("'"&I$2&"'!C21") -> 0 | J5: =INDIRECT("'"&J$2&"'!C21") -> 0
B6: Voided volume Uroflow | C6: Max | D6: =INDIRECT("'"&D$2&"'!M5") -> 0 | E6: =INDIRECT("'"&E$2&"'!M5") -> 0 | F6: =INDIRECT("'"&F$2&"'!M5") -> 0 | G6: =INDIRECT("'"&G$2&"'!M5") -> 0 | H6: =INDIRECT("'"&H$2&"'!M5") -> 0 | I6: =INDIRECT("'"&I$2&"'!M5") -> 0 | J6: =INDIRECT("'"&J$2&"'!M5") -> 0
C7: Gemiddeld | D7: =INDIRECT("'"&D$2&"'!M6") -> 0 | E7: =INDIRECT("'"&E$2&"'!M6") -> 0 | F7: =INDIRECT("'"&F$2&"'!M6") -> 0 | G7: =INDIRECT("'"&G$2&"'!M6") -> 0 | H7: =INDIRECT("'"&H$2&"'!M6") -> 0 | I7: =INDIRECT("'"&I$2&"'!M6") -> 0 | J7: =INDIRECT("'"&J$2&"'!M6") -> 0
B8: Vochtinname | D8: =INDIRECT("'"&D$2&"'!C32") -> 0 | E8: =INDIRECT("'"&E$2&"'!C32") -> 0 | F8: =INDIRECT("'"&F$2&"'!C32") -> 0 | G8: =INDIRECT("'"&G$2&"'!C32") -> 0 | H8: =INDIRECT("'"&H$2&"'!C32") -> 0 | I8: =INDIRECT("'"&I$2&"'!C32") -> 0 | J8: =INDIRECT("'"&J$2&"'!C32") -> 0

Sheet Dropdowns
A1: Ja | B1: 0
A2: Nee | B2: 1 | E2: Druppels | H2: Pamper nat | J2: Klokvormig | L2: Goede dranken | N2: 0
A3: ="" | B3: 2 | E3: Vlekje in onderbroek | H3: Bed nat | J3: Torenvormig | L3: Bruisend | N3: 1
B4: 3 | E4: Onderbroek nat | H4: Pamper nat, soms bed nat | J4: Plateauvormig | L4: Melk na 16u | N4: 2
B5: 4 | E5: Bovenkleding nat | H5: Bed en pamper nat | J5: Staccato | L5: Koffie/thee | N5: 3
B6: 5 | E6: Kousen nat | J6: Gefractioneerd | N6: 4
B7: 6 | E7: Bovenkleding en kousen nat | N7: 5
B8: 7 | E8: Variërend (druppels tot natte broek) | N8: 6
B9: ="" | E9: Variërend (natte broek tot bovenkleding nat) | J9: Intermittent | N9: 7
J10: Continu | N10: 8
N11: 9
E12: Op toilet | N12: 10
E13: Druppels | J13: Vooruitgang | N13: 11
E14: Vlekje in onderbroek | J14: Stabiel | N14: 12
E15: Onderbroek nat | J15: Achteruitgang | N15: 13
E16: Bovenkleding nat | N16: 14
E17: Kousen nat | N17: 15
E18: Bovenkleding en kousen nat | N18: 16
E19: Variërend (druppels tot natte broek) | N19: 17
E20: Variërend (natte broek tot bovenkleding nat) | N20: 18
N21: 19
N22: 20

Sheet Samenvatting doktersbezoeken
A1: Doktersbezoek 1
A6: Doktersbezoek 2

Sheet Database
A1: Waarde | B1: Type | G1: Waarde
A2: Patient | B2: Tekst | G2: ='Algemene info'!B3 -> 0
A3: leeftijd
A4: gewicht
A5: lengte
A6: eerder al 6 maand droog geweest
A7: leeftijd eerste consult voor incontinentie
A8: Medische voorgeschiedenis
A9: Familiale anamnese
A10: Continentie voor urine overdag werd grotendeels bereikt op <…> jaar.
A11: Continentie voor faeces overdag werd grotendeels bereikt op <….> jaar.
A12: Zindelijkheidstraining gestart overdag op <… >.
A13: Zindelijkheidstraining gestart ’s nachts op <…..>.
